<?xml version="1.0"?>
<robot xmlns:xacro="http://www.ros.org/wiki/xacro" name="polou4801">


  <material name="orange">
      <color rgba="1 0.3 0.1 1"/>
  </material>

  <link name="world"></link>

  <joint name="world_to_base" type="fixed">
      <parent link="world" />
      <child link="robot_body" />
      <origin  rpy="0 0 0" xyz="0 0 0" />
  </joint>

  <link name="robot_body">
    <visual>
      <origin xyz="0 0 0" rpy="0 0 0" />
      <geometry>
	      <mesh filename="file:///home/jackfrye/Documents/Robotics/MITCheetah/Modelling/ROS2/workspace/src/ros2_polou4801_motor_control/meshes/polou_4801_body_x100.dae"/>
      </geometry>
      <material name="blue"/>
    </visual>
    <collision>
      <geometry>
	      <mesh filename="file:///home/jackfrye/Documents/Robotics/MITCheetah/Modelling/ROS2/workspace/src/ros2_polou4801_motor_control/meshes/polou_4801_body_x100.dae"/>
      </geometry>
    </collision>
    <inertial>
        <origin xyz="0 0 0" rpy="0 0 0"/>
        <mass value="940" />
        <inertia ixx="0.242833" ixy="0.0" ixz="0.0" iyy="0.242833" iyz="0.0" izz="0.29375" />      
    </inertial>     
  </link>	 

  <joint name="body_to_rotor" type="revolute">
      <parent link="robot_body" />
      <child link="robot_rotor" />
      <axis xyz="0 0 1" />
      <origin  xyz="0 0 0 " rpy="0 0 0" />
      <limit lower="0" upper="${4*pi}" effort="10" velocity="3"/>
  </joint>

  <link name="robot_rotor">
    <visual>
      <origin xyz="0 0 6.5" rpy="0 0 0" />
      <geometry>
	      <mesh filename="file:///home/jackfrye/Documents/Robotics/MITCheetah/Modelling/ROS2/workspace/src/ros2_polou4801_motor_control/meshes/polou_4801_rotor_x100.dae"/>
      </geometry>
      <material name="blue"/>
    </visual>
    <collision>
      <origin xyz="0 0 6.5" rpy="0 0 0" />    
      <geometry>
	      <mesh filename="file:///home/jackfrye/Documents/Robotics/MITCheetah/Modelling/ROS2/workspace/src/ros2_polou4801_motor_control/meshes/polou_4801_rotor_x100.dae"/>
      </geometry>
    </collision>
    <inertial>
        <origin xyz="0 0 6.5" rpy="0 0 0"/>
        <mass value="20" />
        <inertia ixx="0.000016" ixy="0.0" ixz="0.0" iyy="0.000032" iyz="0.0" izz="0.000032" />      
    </inertial>       
   </link>	 

  <joint name="rotor_to_shaft" type="fixed">
      <parent link="robot_rotor" />
      <child link="shaftcollar" />
      <origin  rpy="0 0 0" xyz="0 0 0" />
  </joint>

  <link name="shaftcollar">
    <visual>
      <origin xyz="0 0 7.30" rpy="0 0 0" />
      <geometry>
	      <mesh filename="file:///home/jackfrye/Documents/Robotics/MITCheetah/Modelling/ROS2/workspace/src/ros2_polou4801_motor_control/meshes/shaftcollar_x100.dae"/>
      </geometry>
    </visual>
    <collision>
      <origin xyz="0 0 7.30" rpy="0 0 0" />    
      <geometry>
	      <mesh filename="file:///home/jackfrye/Documents/Robotics/MITCheetah/Modelling/ROS2/workspace/src/ros2_polou4801_motor_control/meshes/shaftcollar_x100.dae"/>
      </geometry>
    </collision>
    <inertial>
        <origin xyz="0 0 7.30" rpy="0 0 0"/>
        <mass value="40" />
        <inertia ixx="0.000653" ixy="0.0" ixz="0.0" iyy="0.000653" iyz="0.0" izz="0.00008" />      
    </inertial>      
   </link>	 

  <joint name="shaft_to_femur" type="fixed">
      <parent link="shaftcollar" />
      <child link="femurleft" />
      <origin  rpy="0 0 0" xyz="0 0 0" />
  </joint>

  <link name="femurleft">
    <visual>
      <origin xyz="0 0 8" rpy="0 0 0" />
      <geometry>
	      <mesh filename="file:///home/jackfrye/Documents/Robotics/MITCheetah/Modelling/ROS2/workspace/src/ros2_polou4801_motor_control/meshes/femurleft_x100.dae"/>
      </geometry>
    </visual>
    <collision>
      <origin xyz="0 0 8" rpy="0 0 0" />    
      <geometry>
	      <mesh filename="file:///home/jackfrye/Documents/Robotics/MITCheetah/Modelling/ROS2/workspace/src/ros2_polou4801_motor_control/meshes/femurleft_x100.dae"/>
      </geometry>
    </collision>
    <inertial>
        <origin xyz="0 0 8" rpy="0 0 0"/>
        <mass value="140" />
        <inertia ixx="0.0" ixy="0.0" ixz="0.0" iyy="0.0" iyz="0.0" izz="0.0" />      
    </inertial>      
   </link>	

  <ros2_control name="GazeboSystem" type="system">
    <hardware>
      <plugin>gazebo_ros2_control/GazeboSystem</plugin>
    </hardware>
    <joint name="body_to_rotor">
      <command_interface name="effort">
        <param name="min">0</param>
        <param name="max">12.5663706144</param>
      </command_interface>
      <state_interface name="position"/>
      <state_interface name="velocity"/>
      <state_interface name="effort"/>
    </joint>
  </ros2_control>

  <gazebo>
    <plugin filename="libgazebo_ros2_control.so" name="gazebo_ros2_control">
      <parameters>/home/jackfrye/Documents/Robotics/MITCheetah/Modelling/ROS2/workspace/src/ros2_polou4801_motor_control/config/joints.yaml</parameters>
    </plugin>
  </gazebo>

</robot>
